<?xml version="1.0" ?>
<!-- =================================================================================== -->
<!-- |    This document was autogenerated by xacro from robot.urdf.xacro               | -->
<!-- |    EDITING THIS FILE BY HAND IS NOT RECOMMENDED                                 | -->
<!-- =================================================================================== -->
<!-- Updated to support proper Ackermann steering: front wheels have a steering joint (revolute Z)
and an inner wheel‑rotation joint (continuous Y). -->
<robot name="robotcar">
  <!-- ───────────────────────────────────────────────
       BASE
       ─────────────────────────────────────────────── -->
  <link name="base_link">
    <visual>
      <geometry>
        <box size="0.133 0.09 0.05"/>
      </geometry>
      <material name="Cyan">
        <color rgba="0 1 1 1"/>
      </material>
    </visual>
  </link>
  <link name="base_footprint"/>
  <joint name="base_joint" type="fixed">
    <parent link="base_link"/>
    <child link="base_footprint"/>
    <origin rpy="0 0 0" xyz="0 0 -0.035"/>
  </joint>
  <!-- ───────────────────────────────────────────────
       MACROS
       ─────────────────────────────────────────────── -->
  <link name="drivewhl_l_link">
    <inertial>
      <origin rpy="0 0 0" xyz="0 0 0"/>
      <mass value="0.1"/>
      <inertia ixx="1e-4" ixy="0" ixz="0" iyy="1e-4" iyz="0" izz="1e-4"/>
    </inertial>
    <visual>
      <origin rpy="1.5707963267948966 0 0" xyz="0 0 0"/>
      <geometry>
        <cylinder length="0.02" radius="0.025"/>
      </geometry>
      <material name="Gray">
        <color rgba="0.5 0.5 0.5 1"/>
      </material>
    </visual>
  </link>
  <joint name="drivewhl_l_joint" type="continuous">
    <parent link="base_link"/>
    <child link="drivewhl_l_link"/>
    <origin rpy="0 0 0" xyz="-0.05 0.057999999999999996 -0.01"/>
    <axis xyz="0 1 0"/>
  </joint>
  <link name="drivewhl_r_link">
    <inertial>
      <origin rpy="0 0 0" xyz="0 0 0"/>
      <mass value="0.1"/>
      <inertia ixx="1e-4" ixy="0" ixz="0" iyy="1e-4" iyz="0" izz="1e-4"/>
    </inertial>
    <visual>
      <origin rpy="1.5707963267948966 0 0" xyz="0 0 0"/>
      <geometry>
        <cylinder length="0.02" radius="0.025"/>
      </geometry>
      <material name="Gray">
        <color rgba="0.5 0.5 0.5 1"/>
      </material>
    </visual>
  </link>
  <joint name="drivewhl_r_joint" type="continuous">
    <parent link="base_link"/>
    <child link="drivewhl_r_link"/>
    <origin rpy="0 0 0" xyz="-0.05 -0.057999999999999996 -0.01"/>
    <axis xyz="0 1 0"/>
  </joint>
  <!-- Steering hub rotates about Z -->
  <link name="steerwhl_l_hub_link">
    <inertial>
      <origin rpy="0 0 0" xyz="0 0 0"/>
      <mass value="0.1"/>
      <inertia ixx="1e-4" ixy="0" ixz="0" iyy="1e-4" iyz="0" izz="1e-4"/>
    </inertial>
  </link>
  <joint name="steerwhl_l_steer_joint" type="revolute">
    <parent link="base_link"/>
    <child link="steerwhl_l_hub_link"/>
    <origin rpy="0 0 0" xyz="0.05 0.057999999999999996 0"/>
    <axis xyz="0 0 1"/>
    <limit effort="5" lower="-0.523598" upper="0.523598" velocity="2"/>
  </joint>
  <!-- Actual wheel rotates about Y inside hub -->
  <link name="steerwhl_l_link">
    <inertial>
      <origin rpy="0 0 0" xyz="0 0 0"/>
      <mass value="0.1"/>
      <inertia ixx="1e-4" ixy="0" ixz="0" iyy="1e-4" iyz="0" izz="1e-4"/>
    </inertial>
    <visual>
      <origin rpy="1.5707963267948966 0 0" xyz="0 0 0"/>
      <geometry>
        <cylinder length="0.02" radius="0.025"/>
      </geometry>
      <material name="Gray">
        <color rgba="0.5 0.5 0.5 1"/>
      </material>
    </visual>
  </link>
  <joint name="steerwhl_l_wheel_joint" type="continuous">
    <parent link="steerwhl_l_hub_link"/>
    <child link="steerwhl_l_link"/>
    <origin rpy="0 0 0" xyz="0 0 -0.01"/>
    <axis xyz="0 1 0"/>
  </joint>
  <!-- Steering hub rotates about Z -->
  <link name="steerwhl_r_hub_link">
    <inertial>
      <origin rpy="0 0 0" xyz="0 0 0"/>
      <mass value="0.1"/>
      <inertia ixx="1e-4" ixy="0" ixz="0" iyy="1e-4" iyz="0" izz="1e-4"/>
    </inertial>
  </link>
  <joint name="steerwhl_r_steer_joint" type="revolute">
    <parent link="base_link"/>
    <child link="steerwhl_r_hub_link"/>
    <origin rpy="0 0 0" xyz="0.05 -0.057999999999999996 0"/>
    <axis xyz="0 0 1"/>
    <limit effort="5" lower="-0.523598" upper="0.523598" velocity="2"/>
  </joint>
  <!-- Actual wheel rotates about Y inside hub -->
  <link name="steerwhl_r_link">
    <inertial>
      <origin rpy="0 0 0" xyz="0 0 0"/>
      <mass value="0.1"/>
      <inertia ixx="1e-4" ixy="0" ixz="0" iyy="1e-4" iyz="0" izz="1e-4"/>
    </inertial>
    <visual>
      <origin rpy="1.5707963267948966 0 0" xyz="0 0 0"/>
      <geometry>
        <cylinder length="0.02" radius="0.025"/>
      </geometry>
      <material name="Gray">
        <color rgba="0.5 0.5 0.5 1"/>
      </material>
    </visual>
  </link>
  <joint name="steerwhl_r_wheel_joint" type="continuous">
    <parent link="steerwhl_r_hub_link"/>
    <child link="steerwhl_r_link"/>
    <origin rpy="0 0 0" xyz="0 0 -0.01"/>
    <axis xyz="0 1 0"/>
  </joint>
  <!-- ───────────────────────────────────────────────
       2D LIDAR (configurable)
       ─────────────────────────────────────────────── -->
  <link name="lidar_link">
    <visual>
      <origin rpy="0 0 0" xyz="0 0 0"/>
      <geometry>
        <cylinder length="0.02" radius="0.03"/>
      </geometry>
      <material name="Black">
        <color rgba="0 0 0 1"/>
      </material>
    </visual>
    <collision>
      <origin rpy="0 0 0" xyz="0 0 0"/>
      <geometry>
        <cylinder length="0.02" radius="0.03"/>
      </geometry>
    </collision>
    <inertial>
      <mass value="0.05"/>
      <origin rpy="0 0 0" xyz="0 0 0"/>
      <inertia ixx="1e-5" ixy="0" ixz="0" iyy="1e-5" iyz="0" izz="1e-5"/>
    </inertial>
  </link>
  <joint name="lidar_joint" type="fixed">
    <parent link="base_link"/>
    <child link="lidar_link"/>
    <origin rpy="0 0 0" xyz="0.05 0.0 0.035"/>
  </joint>
  <!-- Optional Gazebo sensor plugin -->
  <gazebo reference="lidar_link">
    <sensor name="lidar" type="ray">
      <update_rate>20</update_rate>
      <ray>
        <scan>
          <horizontal>
            <samples>500</samples>
            <min_angle>-3.141592653589793</min_angle>
            <max_angle>3.141592653589793</max_angle>
          </horizontal>
        </scan>
        <range>
          <min>0.05</min>
          <max>10.0</max>
        </range>
      </ray>
      <plugin filename="libgazebo_ros_laser.so" name="gazebo_ros_laser">
        <topicName>scan</topicName>
        <frameName>lidar_link</frameName>
      </plugin>
    </sensor>
  </gazebo>
</robot>
